<!-- Same a gym ant but with gear ratio of 30 and sites -->
<mujoco model="ant">

    <visual>
        <rgba rangefinder="0 0 0 0"/>
    </visual>

    <compiler angle="degree" coordinate="local" inertiafromgeom="true"/>
    <option integrator="RK4" timestep="0.01"/>
    <custom>
        <numeric data="0.0 0.0 0.55 1.0 0.0 0.0 0.0 0.0 1.0 0.0 -1.0 0.0 -1.0 0.0 1.0" name="init_qpos"/>
    </custom>
    <default>
        <joint armature="1" damping="1" limited="true"/>
        <geom conaffinity="0" condim="3" density="5.0" friction="1 0.5 0.5" margin="0.01" rgba="0.8 0.6 0.4 1"/>
        <default class="rangefinder">
            <site type="capsule" size=".005 .1" material="site"/>
        </default>
        <default class="imu">
            <site type="box" size=".01 .01 .01" material="site" rgba="0 0 1 .4"/>
        </default>
    </default>
    <asset>
        <texture builtin="gradient" height="100" rgb1="1 1 1" rgb2="0 0 0" type="skybox" width="100"/>
        <texture builtin="flat" height="1278" mark="cross" markrgb="1 1 1" name="texgeom" random="0.01"
                 rgb1="0.8 0.6 0.4" rgb2="0.8 0.6 0.4" type="cube" width="127"/>
        <texture name="texplane" type="2d" builtin="checker" rgb1="1 1 0.5" rgb2="1 1 0.5" width="100" height="100" />
        <material name="MatPlane" reflectance="0.0" shininess="1" specular="1" texrepeat="60 60" texture="texplane"/>
        <material name="geom" texture="texgeom" texuniform="true"/>
        <material name="site" rgba=".5 .5 .5 .3"/>
    </asset>
    <worldbody>
        <light cutoff="100" diffuse="1 1 1" dir="-0 0 -1.3" directional="true" exponent="1" pos="0 0 1.3"
               specular=".1 .1 .1"/>
        <geom name="floor" conaffinity="1" condim="3" material="MatPlane" pos="0 0 -1" rgba="0.8 0.9 0.8 1"
              type="hfield" hfield="hill"/>

        <body name="torso" pos="0 0 0.75">
            <!-- Sensors -->
            <camera euler="90 -90 0" fovy="120" name="rgb" pos="0.0 0 0.6" />
            <site name="rangefinder1" class="rangefinder" fromto="0 0 0.25 0.587785252 0.80901699 0.1" rgba="0 0 0 0"/>
            <site name="rangefinder2" class="rangefinder" fromto="0 0 0.25 0.951056516 0.30901699 0.1" rgba="0 0 0 0"/>
            <site name="rangefinder3" class="rangefinder" fromto="0 0 0.25 0.951056516 -0.30901699 0.1" rgba="0 0 0 0"/>
            <site name="rangefinder4" class="rangefinder" fromto="0 0 0.25 0.587785252 -0.80901699 0.1" rgba="0 0 0 0"/>
            <site name="rangefinder5" class="rangefinder" fromto="0 0 0.25 0.122464680 -1. 0.25" rgba="0 0 0 0"/>
            <site name="rangefinder6" class="rangefinder" fromto="0 0 0.25 -0.587785252 -0.80901699 0.1"
                  rgba="0 0 0 0"/>
            <site name="rangefinder7" class="rangefinder" fromto="0 0 0.25 -0.951056516 -0.30901699 0.1"
                  rgba="0 0 0 0"/>
            <site name="rangefinder8" class="rangefinder" fromto="0 0 0.25 -0.951056516 0.30901699 0.1" rgba="0 0 0 0"/>
            <site name="rangefinder9" class="rangefinder" fromto="0 0 0.25 -0.587785252 0.80901699 0.1" rgba="0 0 0 0"/>
            <site name="rangefinder10" class="rangefinder" fromto="0 0 0.25 -0.244929360 1. 0.1" rgba="0 0 0 0"/>
            <site name="accel1" class="imu" pos="0 0 0.3"/>
            <site name="gyro1" class="imu" pos="0 0 0.3"/>

            <geom name="torso_geom" pos="0 0 0" size="0.25" type="sphere"/>
            <joint armature="0" damping="0" limited="false" margin="0.01" name="root" pos="0 0 0" type="free"/>
            <body name="front_left_leg" pos="0 0 0">
                <geom fromto="0.0 0.0 0.0 0.2 0.2 0.0" name="aux_1_geom" size="0.08" type="capsule"/>
                <body name="aux_1" pos="0.2 0.2 0">
                    <joint axis="0 0 1" name="hip_1" pos="0.0 0.0 0.0" range="-30 30" type="hinge"/>
                    <geom fromto="0.0 0.0 0.0 0.2 0.2 0.0" name="left_leg_geom" size="0.08" type="capsule"/>
                    <body pos="0.2 0.2 0">
                        <joint axis="-1 1 0" name="ankle_1" pos="0.0 0.0 0.0" range="30 70" type="hinge"/>
                        <geom fromto="0.0 0.0 0.0 0.4 0.4 0.0" name="left_ankle_geom" size="0.08" type="capsule"/>
                    </body>
                </body>
            </body>
            <body name="front_right_leg" pos="0 0 0">
                <geom fromto="0.0 0.0 0.0 -0.2 0.2 0.0" name="aux_2_geom" size="0.08" type="capsule"/>
                <body name="aux_2" pos="-0.2 0.2 0">
                    <joint axis="0 0 1" name="hip_2" pos="0.0 0.0 0.0" range="-30 30" type="hinge"/>
                    <geom fromto="0.0 0.0 0.0 -0.2 0.2 0.0" name="right_leg_geom" size="0.08" type="capsule"/>
                    <body pos="-0.2 0.2 0">
                        <joint axis="1 1 0" name="ankle_2" pos="0.0 0.0 0.0" range="-70 -30" type="hinge"/>
                        <geom fromto="0.0 0.0 0.0 -0.4 0.4 0.0" name="right_ankle_geom" size="0.08" type="capsule"/>
                    </body>
                </body>
            </body>
            <body name="back_leg" pos="0 0 0">
                <geom fromto="0.0 0.0 0.0 -0.2 -0.2 0.0" name="aux_3_geom" size="0.08" type="capsule"/>
                <body name="aux_3" pos="-0.2 -0.2 0">
                    <joint axis="0 0 1" name="hip_3" pos="0.0 0.0 0.0" range="-30 30" type="hinge"/>
                    <geom fromto="0.0 0.0 0.0 -0.2 -0.2 0.0" name="back_leg_geom" size="0.08" type="capsule"/>
                    <body pos="-0.2 -0.2 0">
                        <joint axis="-1 1 0" name="ankle_3" pos="0.0 0.0 0.0" range="-70 -30" type="hinge"/>
                        <geom fromto="0.0 0.0 0.0 -0.4 -0.4 0.0" name="third_ankle_geom" size="0.08" type="capsule"/>
                    </body>
                </body>
            </body>
            <body name="right_back_leg" pos="0 0 0">
                <geom fromto="0.0 0.0 0.0 0.2 -0.2 0.0" name="aux_4_geom" size="0.08" type="capsule"/>
                <body name="aux_4" pos="0.2 -0.2 0">
                    <joint axis="0 0 1" name="hip_4" pos="0.0 0.0 0.0" range="-30 30" type="hinge"/>
                    <geom fromto="0.0 0.0 0.0 0.2 -0.2 0.0" name="rightback_leg_geom" size="0.08" type="capsule"/>
                    <body pos="0.2 -0.2 0">
                        <joint axis="1 1 0" name="ankle_4" pos="0.0 0.0 0.0" range="30 70" type="hinge"/>
                        <geom fromto="0.0 0.0 0.0 0.4 -0.4 0.0" name="fourth_ankle_geom" size="0.08" type="capsule"/>
                    </body>
                </body>
            </body>
        </body>
        <!--By default, this goal will be hidden under the floor-->
        <site name="goal" rgba="0 1 1 0.5" pos="0. 0. -1" size="0.5"/>
        <site name="origin" rgba="1 0 0 0.5" pos="0. 0. 0." size="0.1"/>
    </worldbody>
    <actuator>
        <motor ctrllimited="true" ctrlrange="-1.0 1.0" joint="hip_4" gear="30"/>
        <motor ctrllimited="true" ctrlrange="-1.0 1.0" joint="ankle_4" gear="30"/>
        <motor ctrllimited="true" ctrlrange="-1.0 1.0" joint="hip_1" gear="30"/>
        <motor ctrllimited="true" ctrlrange="-1.0 1.0" joint="ankle_1" gear="30"/>
        <motor ctrllimited="true" ctrlrange="-1.0 1.0" joint="hip_2" gear="30"/>
        <motor ctrllimited="true" ctrlrange="-1.0 1.0" joint="ankle_2" gear="30"/>
        <motor ctrllimited="true" ctrlrange="-1.0 1.0" joint="hip_3" gear="30"/>
        <motor ctrllimited="true" ctrlrange="-1.0 1.0" joint="ankle_3" gear="30"/>
    </actuator>
    <sensor>
        <rangefinder name="rangefinder1" noise="0" site="rangefinder1"/>
        <rangefinder name="rangefinder2" noise="0" site="rangefinder2"/>
        <rangefinder name="rangefinder3" noise="0" site="rangefinder3"/>
        <rangefinder name="rangefinder4" noise="0" site="rangefinder4"/>
        <rangefinder name="rangefinder5" noise="0" site="rangefinder5"/>
        <rangefinder name="rangefinder6" noise="0" site="rangefinder6"/>
        <rangefinder name="rangefinder7" noise="0" site="rangefinder7"/>
        <rangefinder name="rangefinder8" noise="0" site="rangefinder8"/>
        <rangefinder name="rangefinder9" noise="0" site="rangefinder9"/>
        <rangefinder name="rangefinder10" noise="0" site="rangefinder10"/>
        <accelerometer name="accel1" noise="0" site="accel1" cutoff="10"/>
        <gyro name="gyro1" noise="0" site="gyro1" cutoff="10"/>
    </sensor>
</mujoco>
